{
 "cells": [
  {
   "cell_type": "code",
   "execution_count": 19,
   "metadata": {},
   "outputs": [],
   "source": [
    "import os"
   ]
  },
  {
   "cell_type": "code",
   "execution_count": 31,
   "metadata": {},
   "outputs": [
    {
     "data": {
      "text/plain": [
       "'/Users/nthabiseng/Desktop'"
      ]
     },
     "execution_count": 31,
     "metadata": {},
     "output_type": "execute_result"
    }
   ],
   "source": [
    "%pwd"
   ]
  },
  {
   "cell_type": "code",
   "execution_count": 41,
   "metadata": {},
   "outputs": [],
   "source": [
    "os.chdir('/Users/nthabiseng/Desktop/text_summarization/')\n"
   ]
  },
  {
   "cell_type": "code",
   "execution_count": null,
   "metadata": {},
   "outputs": [],
   "source": []
  },
  {
   "cell_type": "code",
   "execution_count": 42,
   "metadata": {},
   "outputs": [
    {
     "data": {
      "text/plain": [
       "'/Users/nthabiseng/Desktop/text_summarization'"
      ]
     },
     "execution_count": 42,
     "metadata": {},
     "output_type": "execute_result"
    }
   ],
   "source": [
    "%pwd\n"
   ]
  },
  {
   "cell_type": "code",
   "execution_count": 43,
   "metadata": {},
   "outputs": [],
   "source": [
    "from dataclasses import dataclass\n",
    "from pathlib import Path\n",
    "\n",
    "\n",
    "@dataclass(frozen=True)\n",
    "class DataValidationConfig:\n",
    "    root_dir: Path\n",
    "    STATUS_FILE: str\n",
    "    ALL_REQUIRED_FILES: list"
   ]
  },
  {
   "cell_type": "code",
   "execution_count": 44,
   "metadata": {},
   "outputs": [],
   "source": [
    "from textSummarizer.constants import *\n",
    "from textSummarizer.utils.common import read_yaml, create_directories"
   ]
  },
  {
   "cell_type": "code",
   "execution_count": 45,
   "metadata": {},
   "outputs": [],
   "source": [
    "class ConfigurationManager:\n",
    "    def __init__(\n",
    "        self,\n",
    "        config_filepath = CONFIG_FILE_PATH,\n",
    "        params_filepath = PARAMS_FILE_PATH):\n",
    "\n",
    "        self.config = read_yaml(config_filepath)\n",
    "        self.params = read_yaml(params_filepath)\n",
    "\n",
    "        create_directories([self.config.artifacts_root])\n",
    "\n",
    "\n",
    "    \n",
    "    def get_data_validation_config(self) -> DataValidationConfig:\n",
    "        config = self.config.data_validation\n",
    "\n",
    "        create_directories([config.root_dir])\n",
    "\n",
    "        data_validation_config = DataValidationConfig(\n",
    "            root_dir=config.root_dir,\n",
    "            STATUS_FILE=config.STATUS_FILE,\n",
    "            ALL_REQUIRED_FILES=config.ALL_REQUIRED_FILES,\n",
    "        )\n",
    "\n",
    "        return data_validation_config"
   ]
  },
  {
   "cell_type": "code",
   "execution_count": 46,
   "metadata": {},
   "outputs": [],
   "source": [
    "import os\n",
    "from textSummarizer.logging import logger"
   ]
  },
  {
   "cell_type": "code",
   "execution_count": 47,
   "metadata": {},
   "outputs": [],
   "source": [
    "class DataValiadtion:\n",
    "    def __init__(self, config: DataValidationConfig):\n",
    "        self.config = config\n",
    "\n",
    "\n",
    "    \n",
    "    def validate_all_files_exist(self)-> bool:\n",
    "        try:\n",
    "            validation_status = None\n",
    "\n",
    "            all_files = os.listdir(os.path.join(\"artifacts\",\"data_ingestion\",\"samsum_dataset\"))\n",
    "\n",
    "            for file in all_files:\n",
    "                if file not in self.config.ALL_REQUIRED_FILES:\n",
    "                    validation_status = False\n",
    "                    with open(self.config.STATUS_FILE, 'w') as f:\n",
    "                        f.write(f\"Validation status: {validation_status}\")\n",
    "                else:\n",
    "                    validation_status = True\n",
    "                    with open(self.config.STATUS_FILE, 'w') as f:\n",
    "                        f.write(f\"Validation status: {validation_status}\")\n",
    "\n",
    "            return validation_status\n",
    "        \n",
    "        except Exception as e:\n",
    "            raise e"
   ]
  },
  {
   "cell_type": "code",
   "execution_count": 48,
   "metadata": {},
   "outputs": [
    {
     "name": "stdout",
     "output_type": "stream",
     "text": [
      "[2023-09-10 21:15:49,388: INFO: common: yaml file: config/config.yaml loaded successfully]\n",
      "[2023-09-10 21:15:49,395: INFO: common: yaml file: params.yaml loaded successfully]\n"
     ]
    },
    {
     "name": "stdout",
     "output_type": "stream",
     "text": [
      "[2023-09-10 21:15:49,401: INFO: common: created directory at: artifacts]\n"
     ]
    },
    {
     "ename": "BoxKeyError",
     "evalue": "\"'ConfigBox' object has no attribute 'data_validation'\"",
     "output_type": "error",
     "traceback": [
      "\u001b[0;31m---------------------------------------------------------------------------\u001b[0m",
      "\u001b[0;31mKeyError\u001b[0m                                  Traceback (most recent call last)",
      "File \u001b[0;32m~/opt/anaconda3/envs/textsummarization/lib/python3.8/site-packages/box/box.py:587\u001b[0m, in \u001b[0;36mbox.box.Box.__getitem__\u001b[0;34m()\u001b[0m\n",
      "\u001b[0;31mKeyError\u001b[0m: 'data_validation'",
      "\nThe above exception was the direct cause of the following exception:\n",
      "\u001b[0;31mBoxKeyError\u001b[0m                               Traceback (most recent call last)",
      "File \u001b[0;32m~/opt/anaconda3/envs/textsummarization/lib/python3.8/site-packages/box/box.py:620\u001b[0m, in \u001b[0;36mbox.box.Box.__getattr__\u001b[0;34m()\u001b[0m\n",
      "File \u001b[0;32m~/opt/anaconda3/envs/textsummarization/lib/python3.8/site-packages/box/box.py:608\u001b[0m, in \u001b[0;36mbox.box.Box.__getitem__\u001b[0;34m()\u001b[0m\n",
      "\u001b[0;31mBoxKeyError\u001b[0m: \"'data_validation'\"",
      "\nDuring handling of the above exception, another exception occurred:\n",
      "\u001b[0;31mAttributeError\u001b[0m                            Traceback (most recent call last)",
      "File \u001b[0;32m~/opt/anaconda3/envs/textsummarization/lib/python3.8/site-packages/box/box.py:622\u001b[0m, in \u001b[0;36mbox.box.Box.__getattr__\u001b[0;34m()\u001b[0m\n",
      "\u001b[0;31mAttributeError\u001b[0m: 'ConfigBox' object has no attribute 'data_validation'",
      "\nThe above exception was the direct cause of the following exception:\n",
      "\u001b[0;31mBoxKeyError\u001b[0m                               Traceback (most recent call last)",
      "File \u001b[0;32m~/opt/anaconda3/envs/textsummarization/lib/python3.8/site-packages/box/config_box.py:28\u001b[0m, in \u001b[0;36mbox.config_box.ConfigBox.__getattr__\u001b[0;34m()\u001b[0m\n",
      "File \u001b[0;32m~/opt/anaconda3/envs/textsummarization/lib/python3.8/site-packages/box/box.py:636\u001b[0m, in \u001b[0;36mbox.box.Box.__getattr__\u001b[0;34m()\u001b[0m\n",
      "\u001b[0;31mBoxKeyError\u001b[0m: \"'ConfigBox' object has no attribute 'data_validation'\"",
      "\nDuring handling of the above exception, another exception occurred:\n",
      "\u001b[0;31mKeyError\u001b[0m                                  Traceback (most recent call last)",
      "File \u001b[0;32m~/opt/anaconda3/envs/textsummarization/lib/python3.8/site-packages/box/box.py:587\u001b[0m, in \u001b[0;36mbox.box.Box.__getitem__\u001b[0;34m()\u001b[0m\n",
      "\u001b[0;31mKeyError\u001b[0m: 'data_validation'",
      "\nThe above exception was the direct cause of the following exception:\n",
      "\u001b[0;31mBoxKeyError\u001b[0m                               Traceback (most recent call last)",
      "File \u001b[0;32m~/opt/anaconda3/envs/textsummarization/lib/python3.8/site-packages/box/box.py:620\u001b[0m, in \u001b[0;36mbox.box.Box.__getattr__\u001b[0;34m()\u001b[0m\n",
      "File \u001b[0;32m~/opt/anaconda3/envs/textsummarization/lib/python3.8/site-packages/box/box.py:608\u001b[0m, in \u001b[0;36mbox.box.Box.__getitem__\u001b[0;34m()\u001b[0m\n",
      "\u001b[0;31mBoxKeyError\u001b[0m: \"'data_validation'\"",
      "\nDuring handling of the above exception, another exception occurred:\n",
      "\u001b[0;31mAttributeError\u001b[0m                            Traceback (most recent call last)",
      "File \u001b[0;32m~/opt/anaconda3/envs/textsummarization/lib/python3.8/site-packages/box/box.py:622\u001b[0m, in \u001b[0;36mbox.box.Box.__getattr__\u001b[0;34m()\u001b[0m\n",
      "\u001b[0;31mAttributeError\u001b[0m: 'ConfigBox' object has no attribute 'data_validation'",
      "\nThe above exception was the direct cause of the following exception:\n",
      "\u001b[0;31mBoxKeyError\u001b[0m                               Traceback (most recent call last)",
      "Cell \u001b[0;32mIn[48], line 7\u001b[0m\n\u001b[1;32m      5\u001b[0m     data_validation\u001b[39m.\u001b[39mvalidate_all_files_exist()\n\u001b[1;32m      6\u001b[0m \u001b[39mexcept\u001b[39;00m \u001b[39mException\u001b[39;00m \u001b[39mas\u001b[39;00m e:\n\u001b[0;32m----> 7\u001b[0m     \u001b[39mraise\u001b[39;00m e\n",
      "Cell \u001b[0;32mIn[48], line 3\u001b[0m\n\u001b[1;32m      1\u001b[0m \u001b[39mtry\u001b[39;00m:\n\u001b[1;32m      2\u001b[0m     config \u001b[39m=\u001b[39m ConfigurationManager()\n\u001b[0;32m----> 3\u001b[0m     data_validation_config \u001b[39m=\u001b[39m config\u001b[39m.\u001b[39;49mget_data_validation_config()\n\u001b[1;32m      4\u001b[0m     data_validation \u001b[39m=\u001b[39m DataValiadtion(config\u001b[39m=\u001b[39mdata_validation_config)\n\u001b[1;32m      5\u001b[0m     data_validation\u001b[39m.\u001b[39mvalidate_all_files_exist()\n",
      "Cell \u001b[0;32mIn[45], line 15\u001b[0m, in \u001b[0;36mConfigurationManager.get_data_validation_config\u001b[0;34m(self)\u001b[0m\n\u001b[1;32m     14\u001b[0m \u001b[39mdef\u001b[39;00m \u001b[39mget_data_validation_config\u001b[39m(\u001b[39mself\u001b[39m) \u001b[39m-\u001b[39m\u001b[39m>\u001b[39m DataValidationConfig:\n\u001b[0;32m---> 15\u001b[0m     config \u001b[39m=\u001b[39m \u001b[39mself\u001b[39;49m\u001b[39m.\u001b[39;49mconfig\u001b[39m.\u001b[39;49mdata_validation\n\u001b[1;32m     17\u001b[0m     create_directories([config\u001b[39m.\u001b[39mroot_dir])\n\u001b[1;32m     19\u001b[0m     data_validation_config \u001b[39m=\u001b[39m DataValidationConfig(\n\u001b[1;32m     20\u001b[0m         root_dir\u001b[39m=\u001b[39mconfig\u001b[39m.\u001b[39mroot_dir,\n\u001b[1;32m     21\u001b[0m         STATUS_FILE\u001b[39m=\u001b[39mconfig\u001b[39m.\u001b[39mSTATUS_FILE,\n\u001b[1;32m     22\u001b[0m         ALL_REQUIRED_FILES\u001b[39m=\u001b[39mconfig\u001b[39m.\u001b[39mALL_REQUIRED_FILES,\n\u001b[1;32m     23\u001b[0m     )\n",
      "File \u001b[0;32m~/opt/anaconda3/envs/textsummarization/lib/python3.8/site-packages/box/config_box.py:30\u001b[0m, in \u001b[0;36mbox.config_box.ConfigBox.__getattr__\u001b[0;34m()\u001b[0m\n",
      "File \u001b[0;32m~/opt/anaconda3/envs/textsummarization/lib/python3.8/site-packages/box/box.py:636\u001b[0m, in \u001b[0;36mbox.box.Box.__getattr__\u001b[0;34m()\u001b[0m\n",
      "\u001b[0;31mBoxKeyError\u001b[0m: \"'ConfigBox' object has no attribute 'data_validation'\""
     ]
    }
   ],
   "source": [
    "try:\n",
    "    config = ConfigurationManager()\n",
    "    data_validation_config = config.get_data_validation_config()\n",
    "    data_validation = DataValiadtion(config=data_validation_config)\n",
    "    data_validation.validate_all_files_exist()\n",
    "except Exception as e:\n",
    "    raise e"
   ]
  }
 ],
 "metadata": {
  "kernelspec": {
   "display_name": "textsummarization",
   "language": "python",
   "name": "python3"
  },
  "language_info": {
   "codemirror_mode": {
    "name": "ipython",
    "version": 3
   },
   "file_extension": ".py",
   "mimetype": "text/x-python",
   "name": "python",
   "nbconvert_exporter": "python",
   "pygments_lexer": "ipython3",
   "version": "3.8.17"
  },
  "orig_nbformat": 4
 },
 "nbformat": 4,
 "nbformat_minor": 2
}
